Workbook

Sheet Summary
A1: Store Id | B1: Store Name | C1: Receipt Id | D1: Trans Date | E1: Qty | F1: Item Id | G1: Item Category | H1: Type | I1: Item Desc | J1: MRP | K1: Disc Amount | L1: GST Benefit Discount | M1: Taxable Amount | N1: Tax Rate | O1: Tax Amount | P1: Bill Amount | Q1: HSNSAC | R1: Cust Code | S1: Offer Id | T1: Staff Id | U1: Lens Coating | V1: Tinting Code | W1: Item Group | X1: Entry Status | Y1: GSTIN | Z1: OCI | AA1: Suspended Trans Id | AB1: Batch Id
A2: W122 | B2: Pune - Phoenix MC Mall | C2: #122562109330 | D2: 46115 | E2: 1 | F2: MTM3BL51 | G2: Tomford SG | I2: TF1021-N 01D 3P ELTON ECO | J2: 43000 | K2: 0 | L2: 0 | M2: 36440.68 | N2: 18 | O2: 6559.32 | P2: 43000 | Q2: 90041000 | R2: CS0586640 | T2: S0157-Shirish Mukesh | W2: IG100 | X2: Posted | AA2: W122-562-17742695298
A3: W149 | B3: Bangalore - Indira Nagar2 | C3: #149586105650 | D3: 46125 | E3: 1 | F3: MTM19BR54 | G3: Tomford FR | I3: TF5869-B 052 0 ECO | J3: 29400 | K3: -3782.12 | L3: 0 | M3: 24397.98 | N3: 5 | O3: 1219.9 | P3: 25617.88 | Q3: 90049090 | R3: CS0141358 | T3: D0069-Darshan Y G | W3: IG30 | X3: Posted | Z3: OCIW14926000412 | AA3: W149-586-17741936712
A4: W149 | B4: Bangalore - Indira Nagar2 | C4: #149586105699 | D4: 46130 | E4: 1 | F4: MTM33BR53 | G4: Tomford FR | H4: Frame | I4: TF6106-D-B 052 0 | J4: 44500 | K4: -8900 | L4: 0 | M4: 33904.76 | N4: 5 | O4: 1695.24 | P4: 35600 | Q4: 90031100 | R4: CS0583100 | S4: TF Modstar 20P | T4: D0069-Darshan Y G | W4: IG30 | X4: Posted
A5: W075 | B5: Bangalore - Kormangala | C5: #075536105013 | D5: 46132 | E5: 1 | F5: MTM14BR52 | G5: Tomford FR | H5: Frame | I5: TF5617-B 052 | J5: 32000 | K5: -6400 | L5: 0 | M5: 24380.96 | N5: 5 | O5: 1219.04 | P5: 25600 | Q5: 90049090 | R5: CW075-002364 | T5: F0008-Fathimath Naji | W5: IG30 | X5: Posted | Z5: OCIW07526000235 | AA5: W075-536-17765149970
A6: W073 | B6: Puducherry - Mission Street | C6: #073534109595 | D6: 46133 | E6: 1 | F6: MTM19BR54 | G6: Tomford FR | H6: Frame | I6: TF5869-B 052 0 ECO | J6: 29400 | K6: -4475.36 | L6: 0 | M6: 23737.76 | N6: 5 | O6: 1186.88 | P6: 24924.64 | Q6: 90049090 | R6: CW073-005137 | T6: G0003-G K Rajesh | W6: IG30 | X6: Posted | Z6: OCIW07326000416 | AA6: W073-534-17760585573
A7: W149 | B7: Bangalore - Indira Nagar2 | C7: #149586105731 | D7: 46133 | E7: 1 | F7: MTM17BR49 | G7: Tomford FR | H7: Frame | I7: TF5867-B 052 0 | J7: 29400 | K7: -3528 | L7: 0 | M7: 24640 | N7: 5 | O7: 1232 | P7: 25872 | Q7: 90031100 | R7: CS0196588 | T7: M0113-Md Saeedali K | W7: IG30 | X7: Posted | AA7: W149-586-17748679769
A8: W149 | B8: Bangalore - Indira Nagar2 | C8: #149586105746 | D8: 46134 | E8: 1 | F8: MTM30BL54 | G8: Tomford SG | H8: Sunglass | I8: TF1273-D 01V 0 ECO | J8: 40100 | K8: -8020 | L8: 0 | M8: 27186.44 | N8: 18 | O8: 4893.56 | P8: 32080 | Q8: 90041000 | R8: CW105-0016394 | S8: TF Modstar 20P | T8: R0100-Rakesh Ghosh | W8: IG100 | X8: Posted | AA8: W149-586-17765249802

Sheet Sales & Stocks Report
A1: Sum of Qty | D1: Type
A2: Store Id | B2: Store Name | C2: Trans Date | D2: Frame | E2: Sunglass
A3: W073 | B3: Puducherry - Mission Street | C3: 46133 | D3: 1
A4: W075 | B4: Bangalore - Kormangala | C4: 46132 | D4: 1
A5: W149 | B5: Bangalore - Indira Nagar2 | C5: 46130 | D5: 1
C6: 46133 | D6: 1
C7: 46134 | E7: 1
A8: Grand Total | D8: 4 | E8: 1

Sheet GRAPHICAL
A1: MODSTAR / TOMFORD — SALES PERFORMANCE DASHBOARD
A3: TOTAL SALE QTY WITH RX | D3: SALE QTY FRAME | G3: SALE QTY SUNGLASS | J3: SALE QTY Rx
A4: =SUM('RET WISE SALE'!BA2:BC2) -> 86 | D4: ='RET WISE SALE'!BA2 -> 34 | G4: ='RET WISE SALE'!BB2 -> 8 | J4: ='RET WISE SALE'!BC2 -> 44
A6: INCENTIVE | D6: DISCOUNT | G6: STOCK QTY FRAME | J6: STOCK QTY SUNGLASS
A7: ='RET WISE SALE'!BX2 -> 21000 | D7: =SUM('Raw Sale'!AH2:AH1000) -> 200668.04 | G7: =SUM('RET WISE SALE'!F2) -> 103 | J7: ='RET WISE SALE'!G2 -> 48
A10: Top to Bottom Retail by Qty Sale With out Rx
A11: Retail | B11: Qty Sales | E11: Row Labels | F11: Sum of Qty Sales
A12: INDIRANAGAR 2 | B12: =VLOOKUP($A12,'RET WISE SALE'!B:BX,74,0) -> 11 | E12: LUDHIANA MALHAR ROAD | F12: 1
A13: KORAMANGALA | B13: =VLOOKUP($A13,'RET WISE SALE'!B:BX,74,0) -> 5 | E13: KALYANINAGAR | F13: 1
A14: PUDUCHERRY | B14: =VLOOKUP($A14,'RET WISE SALE'!B:BX,74,0) -> 4 | E14: ARJUN MARG | F14: 1
A15: SILIGURI CITY CENTRE | B15: =VLOOKUP($A15,'RET WISE SALE'!B:BX,74,0) -> 3 | E15: BRIGADE ORION | F15: 1
A16: M5 E City Mall | B16: =VLOOKUP($A16,'RET WISE SALE'!B:BX,74,0) -> 3 | E16: PACIFIC MALL | F16: 1
A17: ALPHA MALL | B17: =VLOOKUP($A17,'RET WISE SALE'!B:BX,74,0) -> 2 | E17: VIZAG SIRIPURAM | F17: 1
A18: HILAND PARK | B18: =VLOOKUP($A18,'RET WISE SALE'!B:BX,74,0) -> 2 | E18: PHOENIX CITADEL | F18: 1
A19: LUDHIANA MALHAR ROAD | B19: =VLOOKUP($A19,'RET WISE SALE'!B:BX,74,0) -> 1 | E19: GIP MALL NOIDA | F19: 1
A20: RANCHI | B20: =VLOOKUP($A20,'RET WISE SALE'!B:BX,74,0) -> 1 | E20: RANCHI | F20: 1
A21: ARJUN MARG | B21: =VLOOKUP($A21,'RET WISE SALE'!B:BX,74,0) -> 1 | E21: ALPHA MALL | F21: 2
A22: PHOENIX MARKETCITY | B22: =VLOOKUP($A22,'RET WISE SALE'!B:BX,74,0) -> 3 | E22: HILAND PARK | F22: 2
A23: VIZAG SIRIPURAM | B23: =VLOOKUP($A23,'RET WISE SALE'!B:BX,74,0) -> 1 | E23: PHOENIX MARKETCITY | F23: 3
... A26: BRIGADE ORION | B26: =VLOOKUP($A26,'RET WISE SALE'!B:BX,74,0) -> 1 | E26: PUDUCHERRY | F26: 4
A27: PHOENIX CITADEL | B27: =VLOOKUP($A27,'RET WISE SALE'!B:BX,74,0) -> 1 | E27: KORAMANGALA | F27: 5 | J27: Sales Mix
A28: PACIFIC MALL | B28: =VLOOKUP($A28,'RET WISE SALE'!B:BX,74,0) -> 1 | E28: INDIRANAGAR 2 | F28: 11 | J28: Segment | K28: Qty Sale | L28: Contribution%
A29: LAKESHORE GATEWAY MALL | B29: =VLOOKUP($A29,'RET WISE SALE'!B:BX,74,0) -> 0 | E29: Grand Total | F29: 42 | J29: Frame | K29: 34 | L29: =$K29/($K$29+$K$30+$K$31) -> 0.39534884
A30: DURGAPUR,JUNCTION MALL | B30: =VLOOKUP($A30,'RET WISE SALE'!B:BX,74,0) -> 0 | J30: Sunglass | K30: 8 | L30: =$K30/($K$29+$K$30+$K$31) -> 0.093023256
A31: ACROPOLIS MALL | B31: =VLOOKUP($A31,'RET WISE SALE'!B:BX,74,0) -> 0 | J31: Lens | K31: 44 | L31: =$K31/($K$29+$K$30+$K$31) -> 0.51162791
A32: BHARTIYA CITY | B32: =VLOOKUP($A32,'RET WISE SALE'!B:BX,74,0) -> 0
A48: Monthly Trend Without Rx
A49: Month | B49: Qty Sales | C49: Incentive
A50: 46054 | B50: =SUM('RET WISE SALE'!I2:J2) -> 1 | C50: =B50*500 -> 500
A51: 46082 | B51: =SUM('RET WISE SALE'!M2:N2) -> 4 | C51: =B51*500 -> 2000 | E51: Row Labels | F51: Qty Sales
A52: 46113 | B52: =SUM('RET WISE SALE'!Q2:R2) -> 9 | C52: =B52*500 -> 4500 | E52: Feb | F52: 1
A53: 46143 | B53: =SUM('RET WISE SALE'!U2:V2) -> 6 | C53: =B53*500 -> 3000 | E53: Mar | F53: 4
A54: 46174 | B54: =SUM('RET WISE SALE'!Y2:Z2) -> 15 | C54: =B54*500 -> 7500 | E54: Apr | F54: 9
A55: 46204 | B55: =SUM('RET WISE SALE'!AC2:AD2) -> 7 | C55: =B55*500 -> 3500 | E55: May | F55: 6
A56: 46235 | B56: =SUM('RET WISE SALE'!AG2:AH2) -> 0 | C56: =B56*500 -> 0 | E56: Jun | F56: 15
E57: Jul | F57: 7
E58: Aug | F58: 0
E59: Grand Total | F59: 42

Sheet RET WISE SALE
A2: Tomford Modstar | E2: . | F2: =SUBTOTAL(9,F5:F25) -> 103 | G2: =SUBTOTAL(9,G5:G25) -> 48 | H2: . | I2: =SUBTOTAL(9,I5:I25) -> 1 | J2: =SUBTOTAL(9,J5:J25) -> 0 | K2: =SUBTOTAL(9,K5:K25) -> 0 | L2: . | M2: =SUBTOTAL(9,M5:M25) -> 3 | N2: =SUBTOTAL(9,N5:N25) -> 1 | O2: =SUBTOTAL(9,O5:O25) -> 2 | P2: . | Q2: =SUBTOTAL(9,Q5:Q25) -> 7 | R2: =SUBTOTAL(9,R5:R25) -> 2 | S2: =SUBTOTAL(9,S5:S25) -> 10 | T2: . | U2: =SUBTOTAL(9,U5:U25) -> 5 | V2: =SUBTOTAL(9,V5:V25) -> 1 | W2: =SUBTOTAL(9,W5:W25) -> 10 | X2: . | Y2: =SUBTOTAL(9,Y5:Y25) -> 9 | Z2: =SUBTOTAL(9,Z5:Z25) -> 6 | AA2: =SUBTOTAL(9,AA5:AA25) -> 10 | AB2: . | AC2: =SUBTOTAL(9,AC5:AC25) -> 7 | AD2: =SUBTOTAL(9,AD5:AD25) -> 0 | AE2: =SUBTOTAL(9,AE5:AE25) -> 8 | AF2: . | AG2: =SUBTOTAL(9,AG5:AG25) -> 2 | AH2: =SUBTOTAL(9,AH5:AH25) -> -2 | AI2: =SUBTOTAL(9,AI5:AI25) -> 4 | AJ2: . | AK2: =SUBTOTAL(9,AK5:AK25) -> 0 | AL2: =SUBTOTAL(9,AL5:AL25) -> 0 | AM2: =SUBTOTAL(9,AM5:AM25) -> 0 | AN2: . | AO2: =SUBTOTAL(9,AO5:AO25) -> 0 | AP2: =SUBTOTAL(9,AP5:AP25) -> 0 | AQ2: =SUBTOTAL(9,AQ5:AQ25) -> 0 | AR2: . | AS2: =SUBTOTAL(9,AS5:AS25) -> 0 | AT2: =SUBTOTAL(9,AT5:AT25) -> 0 | AU2: =SUBTOTAL(9,AU5:AU25) -> 0 | AV2: . | AW2: =SUBTOTAL(9,AW5:AW25) -> 0 | AX2: =SUBTOTAL(9,AX5:AX25) -> 0 | AY2: =SUBTOTAL(9,AY5:AY25) -> 0 | AZ2: . | BA2: =SUBTOTAL(9,BA5:BA25) -> 34 | BB2: =SUBTOTAL(9,BB5:BB25) -> 8 | BC2: =SUBTOTAL(9,BC5:BC25) -> 44 | BD2: . | BE2: =SUBTOTAL(9,BE5:BE25) -> 0 | BF2: =SUBTOTAL(9,BF5:BF25) -> 0 | BG2: =SUBTOTAL(9,BG5:BG25) -> 0 | BH2: . | BI2: =SUBTOTAL(9,BI5:BI25) -> 0 | BJ2: =SUBTOTAL(9,BJ5:BJ25) -> 0 | BK2: =SUBTOTAL(9,BK5:BK25) -> 0 | BL2: . | BM2: =SUBTOTAL(9,BM5:BM25) -> 0 | BN2: =SUBTOTAL(9,BN5:BN25) -> 0 | BO2: =SUBTOTAL(9,BO5:BO25) -> 0 | BP2: . | BQ2: =SUBTOTAL(9,BQ5:BQ25) -> 0 | BR2: =SUBTOTAL(9,BR5:BR25) -> 0 | BS2: =SUBTOTAL(9,BS5:BS25) -> 0 | BT2: . | BV2: . | BW2: =SUBTOTAL(9,BW5:BW25) -> 42 | BX2: =SUBTOTAL(9,BX5:BX25) -> 21000
E3: . | F3: Stock | H3: . | I3: 46054 | L3: . | M3: 46082 | P3: . | Q3: 46113 | T3: . | U3: 46143 | X3: . | Y3: 46174 | AB3: . | AC3: 46204 | AF3: . | AG3: 46235 | AJ3: . | AK3: 46266 | AN3: . | AO3: 46296 | AR3: . | AS3: 46327 | AV3: . | AW3: 46357 | AZ3: . | BA3: Total Sale | BD3: . | BE3: 46266 | BH3: . | BI3: 46296 | BL3: . | BM3: 46327 | BP3: . | BQ3: 46357 | BT3: . | BU3: Total Sale | BV3: . | BW3: Store Incentive
A4: Store Id | B4: Retail | C4: City | D4: BDM | E4: . | F4: Frame | G4: Sunglass | H4: . | I4: Only Fr | J4: Plano Sg | K4: Rx | L4: . | M4: Only Fr | N4: Plano Sg | O4: Rx | P4: . | Q4: Only Fr | R4: Plano Sg | S4: Rx | T4: . | U4: Only Fr | V4: Plano Sg | W4: Rx | X4: . | Y4: Only Fr | Z4: Plano Sg | AA4: Rx | AB4: . | AC4: Only Fr | AD4: Plano Sg | AE4: Rx | AF4: . | AG4: Only Fr | AH4: Plano Sg | AI4: Rx | AJ4: . | AK4: Only Fr | AL4: Plano Sg | AM4: Rx | AN4: . | AO4: Only Fr | AP4: Plano Sg | AQ4: Rx | AR4: . | AS4: Only Fr | AT4: Plano Sg | AU4: Rx | AV4: . | AW4: Only Fr | AX4: Plano Sg | AY4: Rx | AZ4: . | BA4: Only Fr | BB4: Plano Sg | BC4: Rx | BD4: . | BE4: Only Fr | BF4: Plano Sg | BG4: Rx | BH4: . | BI4: Only Fr | BJ4: Plano Sg | BK4: Rx | BL4: . | BM4: Only Fr | BN4: Plano Sg | BO4: Rx | BP4: . | BQ4: Only Fr | BR4: Plano Sg | BS4: Rx | BT4: . | BU4: Total Sale with Rx | BV4: . | BW4: Total Sale Qty without Rx | BX4: Incentive Amount
A5: W024 | B5: LAKESHORE GATEWAY MALL | C5: HYDERABAD | D5: AD | E5: . | F5: 2 | G5: 0 | H5: . | I5: 0 | J5: 0 | K5: 0 | L5: . | M5: 0 | N5: 0 | O5: 0 | P5: . | Q5: 0 | R5: 0 | S5: 0 | T5: . | U5: 0 | V5: 0 | W5: 0 | X5: . | Y5: 0 | Z5: 0 | AA5: 0 | AB5: . | AC5: 0 | AD5: 0 | AE5: 0 | AF5: . | AG5: 0 | AH5: 0 | AI5: 0 | AJ5: . | AK5: 0 | AL5: 0 | AM5: 0 | AN5: . | AO5: 0 | AP5: 0 | AQ5: 0 | AR5: . | AS5: 0 | AT5: 0 | AU5: 0 | AV5: . | AW5: 0 | AX5: 0 | AY5: 0 | AZ5: . | BA5: =SUM(I5,M5,Q5,U5,Y5,AC5,AG5,AK5,AO5,AS5,AW5) -> 0 | BB5: =SUM(J5,N5,R5,V5,Z5,AD5,AH5,AL5,AP5,AT5,AX5) -> 0 | BC5: =SUM(K5,O5,S5,W5,AA5,AE5,AI5,AM5,AQ5,AU5,AY5) -> 0 | BD5: . | BE5: 0 | BF5: 0 | BG5: 0 | BH5: . | BI5: 0 | BJ5: 0 | BK5: 0 | BL5: . | BM5: 0 | BN5: 0 | BO5: 0 | BP5: . | BQ5: 0 | BR5: 0 | BS5: 0 | BT5: . | BU5: =SUM(BA5:BC5) -> 0 | BV5: . | BW5: =SUM(BA5:BB5) -> 0 | BX5: =BW5*500 -> 0
A6: W029 | B6: HILAND PARK | C6: KOLKATA | D6: JD | E6: . | F6: 8 | G6: 0 | H6: . | I6: 0 | J6: 0 | K6: 0 | L6: . | M6: 0 | N6: 0 | O6: 0 | P6: . | Q6: 0 | R6: 0 | S6: 0 | T6: . | U6: 0 | V6: 0 | W6: 0 | X6: . | Y6: 2 | Z6: 0 | AA6: 2 | AB6: . | AC6: 0 | AD6: 0 | AE6: 0 | AF6: . | AG6: 0 | AH6: 0 | AI6: 0 | AJ6: . | AK6: 0 | AL6: 0 | AM6: 0 | AN6: . | AO6: 0 | AP6: 0 | AQ6: 0 | AR6: . | AS6: 0 | AT6: 0 | AU6: 0 | AV6: . | AW6: 0 | AX6: 0 | AY6: 0 | AZ6: . | BA6: =SUM(I6,M6,Q6,U6,Y6,AC6,AG6,AK6,AO6,AS6,AW6) -> 2 | BB6: =SUM(J6,N6,R6,V6,Z6,AD6,AH6,AL6,AP6,AT6,AX6) -> 0 | BC6: =SUM(K6,O6,S6,W6,AA6,AE6,AI6,AM6,AQ6,AU6,AY6) -> 2 | BD6: . | BE6: 0 | BF6: 0 | BG6: 0 | BH6: . | BI6: 0 | BJ6: 0 | BK6: 0 | BL6: . | BM6: 0 | BN6: 0 | BO6: 0 | BP6: . | BQ6: 0 | BR6: 0 | BS6: 0 | BT6: . | BU6: =SUM(BA6:BC6) -> 4 | BV6: . | BW6: =SUM(BA6:BB6) -> 2 | BX6: =BW6*500 -> 1000
A7: W035 | B7: ALPHA MALL | C7: AHMEDABAD | D7: DS | E7: . | F7: 8 | G7: 0 | H7: . | I7: 0 | J7: 0 | K7: 0 | L7: . | M7: 0 | N7: 0 | O7: 0 | P7: . | Q7: 1 | R7: 0 | S7: 2 | T7: . | U7: 0 | V7: 0 | W7: 0 | X7: . | Y7: 1 | Z7: 0 | AA7: 2 | AB7: . | AC7: 0 | AD7: 0 | AE7: 0 | AF7: . | AG7: 0 | AH7: 0 | AI7: 0 | AJ7: . | AK7: 0 | AL7: 0 | AM7: 0 | AN7: . | AO7: 0 | AP7: 0 | AQ7: 0 | AR7: . | AS7: 0 | AT7: 0 | AU7: 0 | AV7: . | AW7: 0 | AX7: 0 | AY7: 0 | AZ7: . | BA7: =SUM(I7,M7,Q7,U7,Y7,AC7,AG7,AK7,AO7,AS7,AW7) -> 2 | BB7: =SUM(J7,N7,R7,V7,Z7,AD7,AH7,AL7,AP7,AT7,AX7) -> 0 | BC7: =SUM(K7,O7,S7,W7,AA7,AE7,AI7,AM7,AQ7,AU7,AY7) -> 4 | BD7: . | BE7: 0 | BF7: 0 | BG7: 0 | BH7: . | BI7: 0 | BJ7: 0 | BK7: 0 | BL7: . | BM7: 0 | BN7: 0 | BO7: 0 | BP7: . | BQ7: 0 | BR7: 0 | BS7: 0 | BT7: . | BU7: =SUM(BA7:BC7) -> 6 | BV7: . | BW7: =SUM(BA7:BB7) -> 2 | BX7: =BW7*500 -> 1000
A8: W038 | B8: GIP MALL NOIDA | C8: NOIDA | D8: AD | E8: . | F8: 5 | G8: 0 | H8: . | I8: 1 | J8: 0 | K8: 0 | L8: . | M8: 0 | N8: 0 | O8: 0 | P8: . | Q8: 0 | R8: 0 | S8: 0 | T8: . | U8: 0 | V8: 0 | W8: 0 | X8: . | Y8: 0 | Z8: 0 | AA8: 0 | AB8: . | AC8: 0 | AD8: 0 | AE8: 0 | AF8: . | AG8: 0 | AH8: 0 | AI8: 0 | AJ8: . | AK8: 0 | AL8: 0 | AM8: 0 | AN8: . | AO8: 0 | AP8: 0 | AQ8: 0 | AR8: . | AS8: 0 | AT8: 0 | AU8: 0 | AV8: . | AW8: 0 | AX8: 0 | AY8: 0 | AZ8: . | BA8: =SUM(I8,M8,Q8,U8,Y8,AC8,AG8,AK8,AO8,AS8,AW8) -> 1 | BB8: =SUM(J8,N8,R8,V8,Z8,AD8,AH8,AL8,AP8,AT8,AX8) -> 0 | BC8: =SUM(K8,O8,S8,W8,AA8,AE8,AI8,AM8,AQ8,AU8,AY8) -> 0 | BD8: . | BE8: 0 | BF8: 0 | BG8: 0 | BH8: . | BI8: 0 | BJ8: 0 | BK8: 0 | BL8: . | BM8: 0 | BN8: 0 | BO8: 0 | BP8: . | BQ8: 0 | BR8: 0 | BS8: 0 | BT8: . | BU8: =SUM(BA8:BC8) -> 1 | BV8: . | BW8: =SUM(BA8:BB8) -> 1 | BX8: =BW8*500 -> 500
A9: W063 | B9: KALYANINAGAR | C9: PUNE | D9: DS | E9: . | F9: 1 | G9: 0 | H9: . | I9: 0 | J9: 0 | K9: 0 | L9: . | M9: 0 | N9: 0 | O9: 0 | P9: . | Q9: 0 | R9: 0 | S9: 0 | T9: . | U9: 0 | V9: 0 | W9: 0 | X9: . | Y9: 0 | Z9: 0 | AA9: 0 | AB9: . | AC9: 1 | AD9: 0 | AE9: 0 | AF9: . | AG9: 0 | AH9: 0 | AI9: 0 | AJ9: . | AK9: 0 | AL9: 0 | AM9: 0 | AN9: . | AO9: 0 | AP9: 0 | AQ9: 0 | AR9: . | AS9: 0 | AT9: 0 | AU9: 0 | AV9: . | AW9: 0 | AX9: 0 | AY9: 0 | AZ9: . | BA9: =SUM(I9,M9,Q9,U9,Y9,AC9,AG9,AK9,AO9,AS9,AW9) -> 1 | BB9: =SUM(J9,N9,R9,V9,Z9,AD9,AH9,AL9,AP9,AT9,AX9) -> 0 | BC9: =SUM(K9,O9,S9,W9,AA9,AE9,AI9,AM9,AQ9,AU9,AY9) -> 0 | BD9: . | BE9: 0 | BF9: 0 | BG9: 0 | BH9: . | BI9: 0 | BJ9: 0 | BK9: 0 | BL9: . | BM9: 0 | BN9: 0 | BO9: 0 | BP9: . | BQ9: 0 | BR9: 0 | BS9: 0 | BT9: . | BU9: =SUM(BA9:BC9) -> 1 | BV9: . | BW9: =SUM(BA9:BB9) -> 1 | BX9: =BW9*500 -> 500
A10: W073 | B10: PUDUCHERRY | C10: PUDUCHERRY | D10: DN | E10: . | F10: 7 | G10: 0 | H10: . | I10: 0 | J10: 0 | K10: 0 | L10: . | M10: 0 | N10: 0 | O10: 0 | P10: . | Q10: 1 | R10: 0 | S10: 2 | T10: . | U10: 1 | V10: 0 | W10: 2 | X10: . | Y10: 1 | Z10: 0 | AA10: 0 | AB10: . | AC10: 0 | AD10: 0 | AE10: 0 | AF10: . | AG10: 1 | AH10: 0 | AI10: 2 | AJ10: . | AK10: 0 | AL10: 0 | AM10: 0 | AN10: . | AO10: 0 | AP10: 0 | AQ10: 0 | AR10: . | AS10: 0 | AT10: 0 | AU10: 0 | AV10: . | AW10: 0 | AX10: 0 | AY10: 0 | AZ10: . | BA10: =SUM(I10,M10,Q10,U10,Y10,AC10,AG10,AK10,AO10,AS10,AW10) -> 4 | BB10: =SUM(J10,N10,R10,V10,Z10,AD10,AH10,AL10,AP10,AT10,AX10) -> 0 | BC10: =SUM(K10,O10,S10,W10,AA10,AE10,AI10,AM10,AQ10,AU10,AY10) -> 6 | BD10: . | BE10: 0 | BF10: 0 | BG10: 0 | BH10: . | BI10: 0 | BJ10: 0 | BK10: 0 | BL10: . | BM10: 0 | BN10: 0 | BO10: 0 | BP10: . | BQ10: 0 | BR10: 0 | BS10: 0 | BT10: . | BU10: =SUM(BA10:BC10) -> 10 | BV10: . | BW10: =SUM(BA10:BB10) -> 4 | BX10: =BW10*500 -> 2000
A11: W075 | B11: KORAMANGALA | C11: BENGALURU | D11: DN | E11: . | F11: 5 | G11: 0 | H11: . | I11: 0 | J11: 0 | K11: 0 | L11: . | M11: 0 | N11: 0 | O11: 0 | P11: . | Q11: 1 | R11: 0 | S11: 2 | T11: . | U11: 2 | V11: 0 | W11: 2 | X11: . | Y11: 1 | Z11: 0 | AA11: 0 | AB11: . | AC11: 1 | AD11: 0 | AE11: 2 | AF11: . | AG11: 0 | AH11: 0 | AI11: 0 | AJ11: . | AK11: 0 | AL11: 0 | AM11: 0 | AN11: . | AO11: 0 | AP11: 0 | AQ11: 0 | AR11: . | AS11: 0 | AT11: 0 | AU11: 0 | AV11: . | AW11: 0 | AX11: 0 | AY11: 0 | AZ11: . | BA11: =SUM(I11,M11,Q11,U11,Y11,AC11,AG11,AK11,AO11,AS11,AW11) -> 5 | BB11: =SUM(J11,N11,R11,V11,Z11,AD11,AH11,AL11,AP11,AT11,AX11) -> 0 | BC11: =SUM(K11,O11,S11,W11,AA11,AE11,AI11,AM11,AQ11,AU11,AY11) -> 6 | BD11: . | BE11: 0 | BF11: 0 | BG11: 0 | BH11: . | BI11: 0 | BJ11: 0 | BK11: 0 | BL11: . | BM11: 0 | BN11: 0 | BO11: 0 | BP11: . | BQ11: 0 | BR11: 0 | BS11: 0 | BT11: . | BU11: =SUM(BA11:BC11) -> 11 | BV11: . | BW11: =SUM(BA11:BB11) -> 5 | BX11: =BW11*500 -> 2500
A12: W095 | B12: DURGAPUR,JUNCTION MALL | C12: DURGAPUR | D12: JD | E12: . | F12: 9 | G12: 0 | H12: . | I12: 0 | J12: 0 | K12: 0 | L12: . | M12: 0 | N12: 0 | O12: 0 | P12: . | Q12: 0 | R12: 0 | S12: 0 | T12: . | U12: 0 | V12: 0 | W12: 0 | X12: . | Y12: 0 | Z12: 0 | AA12: 0 | AB12: . | AC12: 0 | AD12: 0 | AE12: 0 | AF12: . | AG12: 0 | AH12: 0 | AI12: 0 | AJ12: . | AK12: 0 | AL12: 0 | AM12: 0 | AN12: . | AO12: 0 | AP12: 0 | AQ12: 0 | AR12: . | AS12: 0 | AT12: 0 | AU12: 0 | AV12: . | AW12: 0 | AX12: 0 | AY12: 0 | AZ12: . | BA12: =SUM(I12,M12,Q12,U12,Y12,AC12,AG12,AK12,AO12,AS12,AW12) -> 0 | BB12: =SUM(J12,N12,R12,V12,Z12,AD12,AH12,AL12,AP12,AT12,AX12) -> 0 | BC12: =SUM(K12,O12,S12,W12,AA12,AE12,AI12,AM12,AQ12,AU12,AY12) -> 0 | BD12: . | BE12: 0 | BF12: 0 | BG12: 0 | BH12: . | BI12: 0 | BJ12: 0 | BK12: 0 | BL12: . | BM12: 0 | BN12: 0 | BO12: 0 | BP12: . | BQ12: 0 | BR12: 0 | BS12: 0 | BT12: . | BU12: =SUM(BA12:BC12) -> 0 | BV12: . | BW12: =SUM(BA12:BB12) -> 0 | BX12: =BW12*500 -> 0
A13: W110 | B13: LUDHIANA MALHAR ROAD | C13: LUDHIANA | D13: AD | E13: . | F13: 10 | G13: 3 | H13: . | I13: 0 | J13: 0 | K13: 0 | L13: . | M13: 0 | N13: 0 | O13: 0 | P13: . | Q13: 0 | R13: 0 | S13: 0 | T13: . | U13: 0 | V13: 0 | W13: 0 | X13: . | Y13: 1 | Z13: 0 | AA13: 2 | AB13: . | AC13: 0 | AD13: 0 | AE13: 0 | AF13: . | AG13: 0 | AH13: 0 | AI13: 0 | AJ13: . | AK13: 0 | AL13: 0 | AM13: 0 | AN13: . | AO13: 0 | AP13: 0 | AQ13: 0 | AR13: . | AS13: 0 | AT13: 0 | AU13: 0 | AV13: . | AW13: 0 | AX13: 0 | AY13: 0 | AZ13: . | BA13: =SUM(I13,M13,Q13,U13,Y13,AC13,AG13,AK13,AO13,AS13,AW13) -> 1 | BB13: =SUM(J13,N13,R13,V13,Z13,AD13,AH13,AL13,AP13,AT13,AX13) -> 0 | BC13: =SUM(K13,O13,S13,W13,AA13,AE13,AI13,AM13,AQ13,AU13,AY13) -> 2 | BD13: . | BE13: 0 | BF13: 0 | BG13: 0 | BH13: . | BI13: 0 | BJ13: 0 | BK13: 0 | BL13: . | BM13: 0 | BN13: 0 | BO13: 0 | BP13: . | BQ13: 0 | BR13: 0 | BS13: 0 | BT13: . | BU13: =SUM(BA13:BC13) -> 3 | BV13: . | BW13: =SUM(BA13:BB13) -> 1 | BX13: =BW13*500 -> 500
A14: W112 | B14: RANCHI | C14: RANCHI | D14: JD | E14: . | F14: 0 | G14: 6 | H14: . | I14: 0 | J14: 0 | K14: 0 | L14: . | M14: 0 | N14: 0 | O14: 0 | P14: . | Q14: 0 | R14: 0 | S14: 0 | T14: . | U14: 0 | V14: 1 | W14: 2 | X14: . | Y14: 0 | Z14: 0 | AA14: 0 | AB14: . | AC14: 0 | AD14: 0 | AE14: 0 | AF14: . | AG14: 0 | AH14: 0 | AI14: 0 | AJ14: . | AK14: 0 | AL14: 0 | AM14: 0 | AN14: . | AO14: 0 | AP14: 0 | AQ14: 0 | AR14: . | AS14: 0 | AT14: 0 | AU14: 0 | AV14: . | AW14: 0 | AX14: 0 | AY14: 0 | AZ14: . | BA14: =SUM(I14,M14,Q14,U14,Y14,AC14,AG14,AK14,AO14,AS14,AW14) -> 0 | BB14: =SUM(J14,N14,R14,V14,Z14,AD14,AH14,AL14,AP14,AT14,AX14) -> 1 | BC14: =SUM(K14,O14,S14,W14,AA14,AE14,AI14,AM14,AQ14,AU14,AY14) -> 2 | BD14: . | BE14: 0 | BF14: 0 | BG14: 0 | BH14: . | BI14: 0 | BJ14: 0 | BK14: 0 | BL14: . | BM14: 0 | BN14: 0 | BO14: 0 | BP14: . | BQ14: 0 | BR14: 0 | BS14: 0 | BT14: . | BU14: =SUM(BA14:BC14) -> 3 | BV14: . | BW14: =SUM(BA14:BB14) -> 1 | BX14: =BW14*500 -> 500
A15: W117 | B15: ARJUN MARG | C15: GURUGRAM | D15: AD | E15: . | F15: 10 | G15: 0 | H15: . | I15: 0 | J15: 0 | K15: 0 | L15: . | M15: 0 | N15: 0 | O15: 0 | P15: . | Q15: 0 | R15: 0 | S15: 0 | T15: . | U15: 1 | V15: 0 | W15: 2 | X15: . | Y15: 0 | Z15: 0 | AA15: 0 | AB15: . | AC15: 0 | AD15: 0 | AE15: 0 | AF15: . | AG15: 0 | AH15: 0 | AI15: 0 | AJ15: . | AK15: 0 | AL15: 0 | AM15: 0 | AN15: . | AO15: 0 | AP15: 0 | AQ15: 0 | AR15: . | AS15: 0 | AT15: 0 | AU15: 0 | AV15: . | AW15: 0 | AX15: 0 | AY15: 0 | AZ15: . | BA15: =SUM(I15,M15,Q15,U15,Y15,AC15,AG15,AK15,AO15,AS15,AW15) -> 1 | BB15: =SUM(J15,N15,R15,V15,Z15,AD15,AH15,AL15,AP15,AT15,AX15) -> 0 | BC15: =SUM(K15,O15,S15,W15,AA15,AE15,AI15,AM15,AQ15,AU15,AY15) -> 2 | BD15: . | BE15: 0 | BF15: 0 | BG15: 0 | BH15: . | BI15: 0 | BJ15: 0 | BK15: 0 | BL15: . | BM15: 0 | BN15: 0 | BO15: 0 | BP15: . | BQ15: 0 | BR15: 0 | BS15: 0 | BT15: . | BU15: =SUM(BA15:BC15) -> 3 | BV15: . | BW15: =SUM(BA15:BB15) -> 1 | BX15: =BW15*500 -> 500
A16: W118 | B16: ACROPOLIS MALL | C16: KOLKATA | D16: JD | E16: . | F16: 4 | G16: 0 | H16: . | I16: 0 | J16: 0 | K16: 0 | L16: . | M16: 0 | N16: 0 | O16: 0 | P16: . | Q16: 0 | R16: 0 | S16: 0 | T16: . | U16: 0 | V16: 0 | W16: 0 | X16: . | Y16: 0 | Z16: 0 | AA16: 0 | AB16: . | AC16: 0 | AD16: 0 | AE16: 0 | AF16: . | AG16: 0 | AH16: 0 | AI16: 0 | AJ16: . | AK16: 0 | AL16: 0 | AM16: 0 | AN16: . | AO16: 0 | AP16: 0 | AQ16: 0 | AR16: . | AS16: 0 | AT16: 0 | AU16: 0 | AV16: . | AW16: 0 | AX16: 0 | AY16: 0 | AZ16: . | BA16: =SUM(I16,M16,Q16,U16,Y16,AC16,AG16,AK16,AO16,AS16,AW16) -> 0 | BB16: =SUM(J16,N16,R16,V16,Z16,AD16,AH16,AL16,AP16,AT16,AX16) -> 0 | BC16: =SUM(K16,O16,S16,W16,AA16,AE16,AI16,AM16,AQ16,AU16,AY16) -> 0 | BD16: . | BE16: 0 | BF16: 0 | BG16: 0 | BH16: . | BI16: 0 | BJ16: 0 | BK16: 0 | BL16: . | BM16: 0 | BN16: 0 | BO16: 0 | BP16: . | BQ16: 0 | BR16: 0 | BS16: 0 | BT16: . | BU16: =SUM(BA16:BC16) -> 0 | BV16: . | BW16: =SUM(BA16:BB16) -> 0 | BX16: =BW16*500 -> 0
... A25: W161 | B25: M5 E City Mall | C25: BENGALURU | D25: DN | E25: . | F25: 7 | G25: 0 | H25: . | I25: 0 | J25: 0 | K25: 0 | L25: . | M25: 2 | N25: 0 | O25: 2 | P25: . | Q25: 0 | R25: 0 | S25: 0 | T25: . | U25: 0 | V25: 0 | W25: 0 | X25: . | Y25: 1 | Z25: 0 | AA25: 2 | AB25: . | AC25: 0 | AD25: 0 | AE25: 0 | AF25: . | AG25: 0 | AH25: 0 | AI25: 0 | AJ25: . | AK25: 0 | AL25: 0 | AM25: 0 | AN25: . | AO25: 0 | AP25: 0 | AQ25: 0 | AR25: . | AS25: 0 | AT25: 0 | AU25: 0 | AV25: . | AW25: 0 | AX25: 0 | AY25: 0 | AZ25: . | BA25: =SUM(I25,M25,Q25,U25,Y25,AC25,AG25,AK25,AO25,AS25,AW25) -> 3 | BB25: =SUM(J25,N25,R25,V25,Z25,AD25,AH25,AL25,AP25,AT25,AX25) -> 0 | BC25: =SUM(K25,O25,S25,W25,AA25,AE25,AI25,AM25,AQ25,AU25,AY25) -> 4 | BD25: . | BE25: 0 | BF25: 0 | BG25: 0 | BH25: . | BI25: 0 | BJ25: 0 | BK25: 0 | BL25: . | BM25: 0 | BN25: 0 | BO25: 0 | BP25: . | BQ25: 0 | BR25: 0 | BS25: 0 | BT25: . | BU25: =SUM(BA25:BC25) -> 7 | BV25: . | BW25: =SUM(BA25:BB25) -> 3 | BX25: =BW25*500 -> 1500

Sheet Pivot
A3: Sum of Qty | E3: Month | F3: Bill Type
E4: 46235 | F4: 46235 | G4: 46235 | H4: Grand Total
A5: Store Id | B5: Store Name | C5: City | D5: BDM | E5: Only Fr | F5: Plano Sg | G5: Rx
A6: W073 | B6: Puducherry - Mission Street | C6: PUDUCHERRY | D6: D. N.CHOWDHURY | E6: 1 | G6: 2 | H6: 3
A7: W160 | B7: Dehradun - Pacific Mall | C7: DEHRADUN | D7: AMANDEEP SINGH GILL | F7: -2 | H7: -2
A8: W127 | B8: Vizag - Siripuram | C8: VIZAG | D8: AMANDEEP SINGH GILL | E8: 1 | G8: 2 | H8: 3
A9: Grand Total | E9: 2 | F9: -2 | G9: 4 | H9: 4

Sheet Raw Sale
A1: Month | B1: Store Id | C1: Store Name | D1: Receipt Id | E1: Sales Type | F1: Trans Date | G1: Qty | H1: Item Id | I1: Item Category | J1: Item Desc | K1: MRP | L1: Disc Amount | M1: GST Benefit Discount | N1: Taxable Amount | O1: Tax Rate | P1: Tax Amount | Q1: Bill Amount | R1: HSNSAC | S1: Cust Code | T1: Offer Id | U1: Staff Id | V1: Lens Coating | W1: Tinting Code | X1: Item Group | Y1: Entry Status | Z1: GSTIN | AA1: OCI | AB1: Suspended Trans Id | AC1: Batch Id | AD1: Bill Type | AE1: City | AF1: BDM | AG1: Disc Amount | AH1: Disc Amount without Rx | AI1: Incentive Amount
A2: 46054 | B2: W038 | C2: Noida - Unitech | D2: #038524104929 | F2: 46074 | G2: 1 | H2: MTM27GR50 | I2: Tomford FR | J2: TF5963-B 020 0 ECO | K2: 39500 | L2: -3160 | M2: 0 | N2: 34609.52 | O2: 5 | P2: 1730.48 | Q2: 36340 | R2: 90031100 | S2: CS0091648 | U2: D0024-Dhirendra Kr M | X2: IG30 | Y2: Posted | AD2: Only Fr | AE2: =IFERROR(VLOOKUP($B2,Sheet3!B:D,3,0),"") -> NOIDA | AF2: =IFERROR(VLOOKUP($B2,Sheet3!B:H,7,0),"") -> AMANDEEP SINGH GILL | AG2: =-(L2) -> 3160 | AH2: =-(L2) -> 3160 | AI2: =G2*500 -> 500
A3: 46082 | B3: W160 | C3: Dehradun - Pacific Mall | D3: #160598102043 | F3: 46082 | G3: 1 | H3: MTM27GR50 | I3: Tomford FR | J3: TF5963-B 020 0 ECO | K3: 39500 | L3: -4209 | M3: 0 | N3: 33610.48 | O3: 5 | P3: 1680.52 | Q3: 35291 | R3: 90031100 | S3: CW105-0014155 | U3: N0042-Nitesh Singh N | X3: IG30 | Y3: Posted | AD3: Only Fr | AE3: =IFERROR(VLOOKUP($B3,Sheet3!B:D,3,0),"") -> DEHRADUN | AF3: =IFERROR(VLOOKUP($B3,Sheet3!B:H,7,0),"") -> AMANDEEP SINGH GILL | AG3: =-(L3) -> 4209 | AH3: =-(L3) -> 4209 | AI3: =G3*500 -> 500
A4: 46082 | B4: W161 | C4: Bangalore - M5 Mall | D4: #161599101873 | F4: 46084 | G4: 1 | H4: MTM18BL54 | I4: Tomford FR | J4: TF5869-B 001 0 ECO | K4: 29400 | L4: -2400 | M4: 0 | N4: 25714.28 | O4: 5 | P4: 1285.72 | Q4: 27000 | R4: 90031100 | S4: CS0131725 | U4: K0058-K Salim Malik | X4: IG30 | Y4: Posted | AD4: Only Fr | AE4: =IFERROR(VLOOKUP($B4,Sheet3!B:D,3,0),"") -> BENGALURU | AF4: =IFERROR(VLOOKUP($B4,Sheet3!B:H,7,0),"") -> D. N.CHOWDHURY | AG4: =-(L4) -> 2400 | AH4: =-(L4) -> 2400 | AI4: =G4*500 -> 500
A5: 46082 | B5: W131 | C5: Bangalore - Brigade Orion | D5: #131570110257 | F5: 46095 | G5: 1 | H5: MTM34GL51 | I5: Tomford SG | J5: TF248 52E 1/3 HENRY (BROWN) PHOTOCHROMIC | K5: 47500 | L5: -5500 | M5: 0 | N5: 35593.22 | O5: 18 | P5: 6406.78 | Q5: 42000 | R5: 90041000 | S5: CW131-0004203 | U5: M0075-M S Nachappa | X5: IG100 | Y5: Posted | AB5: W131-570-17730406855 | AD5: Plano Sg | AE5: =IFERROR(VLOOKUP($B5,Sheet3!B:D,3,0),"") -> BENGALURU | AF5: =IFERROR(VLOOKUP($B5,Sheet3!B:H,7,0),"") -> D. N.CHOWDHURY | AG5: =-(L5) -> 5500 | AH5: =-(L5) -> 5500 | AI5: =G5*500 -> 500
A6: 46082 | B6: W161 | C6: Bangalore - M5 Mall | D6: #161599102018 | F6: 46106 | G6: 1 | H6: MTM17BR49 | I6: Tomford FR | J6: TF5867-B 052 0 | K6: 29400 | L6: 0 | M6: 0 | N6: 28000 | O6: 5 | P6: 1400 | Q6: 29400 | R6: 90049090 | S6: CS0586897 | T6: GST Discount | U6: R0059-R Balachandran | X6: IG30 | Y6: Posted | AA6: OCIW16126000200 | AB6: W161-599-17743689444 | AD6: Only Fr | AE6: =IFERROR(VLOOKUP($B6,Sheet3!B:D,3,0),"") -> BENGALURU | AF6: =IFERROR(VLOOKUP($B6,Sheet3!B:H,7,0),"") -> D. N.CHOWDHURY | AG6: =-(L6) -> 0 | AH6: =-(L6) -> 0 | AI6: =G6*500 -> 500
A7: 46082 | B7: W161 | C7: Bangalore - M5 Mall | D7: #161599102018 | F7: 46106 | G7: 1 | H7: 11178 | I7: Crizal FSV | J7: 1.50 Crizal FSV Clear Easy Pro BCT | K7: 1350 | L7: 0 | M7: -84.38 | N7: 1205.36 | O7: 5 | P7: 60.26 | Q7: 1265.62 | R7: 90049090 | S7: CS0586897 | U7: R0059-R Balachandran | V7: CRIZALESPR | X7: IG001 | Y7: Posted | AA7: OCIW16126000200 | AB7: W161-599-17743689444 | AD7: Rx | AE7: =IFERROR(VLOOKUP($B7,Sheet3!B:D,3,0),"") -> BENGALURU | AF7: =IFERROR(VLOOKUP($B7,Sheet3!B:H,7,0),"") -> D. N.CHOWDHURY | AG7: =-(L7) -> 0 | AH7: 0
A8: 46082 | B8: W161 | C8: Bangalore - M5 Mall | D8: #161599102018 | F8: 46106 | G8: 1 | H8: 11178 | I8: Crizal FSV | J8: 1.50 Crizal FSV Clear Easy Pro BCT | K8: 1350 | L8: 0 | M8: -84.38 | N8: 1205.36 | O8: 5 | P8: 60.26 | Q8: 1265.62 | R8: 90049090 | S8: CS0586897 | T8: GST Discount | U8: R0059-R Balachandran | V8: CRIZALESPR | X8: IG001 | Y8: Posted | AA8: OCIW16126000200 | AB8: W161-599-17743689444 | AD8: Rx | AE8: =IFERROR(VLOOKUP($B8,Sheet3!B:D,3,0),"") -> BENGALURU | AF8: =IFERROR(VLOOKUP($B8,Sheet3!B:H,7,0),"") -> D. N.CHOWDHURY | AG8: =-(L8) -> 0 | AH8: 0
A9: 46113 | B9: W122 | C9: Pune - Phoenix MC Mall | D9: #122562109330 | F9: 46115 | G9: 1 | H9: MTM3BL51 | I9: Tomford SG | J9: TF1021-N 01D 3P ELTON ECO | K9: 43000 | L9: 0 | M9: 0 | N9: 36440.68 | O9: 18 | P9: 6559.32 | Q9: 43000 | R9: 90041000 | S9: CS0586640 | U9: S0157-Shirish Mukesh | X9: IG100 | Y9: Posted | AB9: W122-562-17742695298 | AD9: Plano Sg | AE9: =IFERROR(VLOOKUP($B9,Sheet3!B:D,3,0),"") -> PUNE | AF9: =IFERROR(VLOOKUP($B9,Sheet3!B:H,7,0),"") -> DIGVIJAY SINGH | AG9: =-(L9) -> 0 | AH9: =-(L9) -> 0 | AI9: =G9*500 -> 500
A10: 46113 | B10: W149 | C10: Bangalore - Indira Nagar2 | D10: #149586105650 | F10: 46125 | G10: 1 | H10: MTM19BR54 | I10: Tomford FR | J10: TF5869-B 052 0 ECO | K10: 29400 | L10: -3782.12 | M10: 0 | N10: 24397.98 | O10: 5 | P10: 1219.9 | Q10: 25617.88 | R10: 90049090 | S10: CS0141358 | U10: D0069-Darshan Y G | X10: IG30 | Y10: Posted | AA10: OCIW14926000412 | AB10: W149-586-17741936712 | AD10: Only Fr | AE10: =IFERROR(VLOOKUP($B10,Sheet3!B:D,3,0),"") -> BENGALURU | AF10: =IFERROR(VLOOKUP($B10,Sheet3!B:H,7,0),"") -> D. N.CHOWDHURY | AG10: =-(L10) -> 3782.12 | AH10: =-(L10) -> 3782.12 | AI10: =G10*500 -> 500
A11: 46113 | B11: W149 | C11: Bangalore - Indira Nagar2 | D11: #149586105650 | F11: 46125 | G11: 1 | H11: 9510992483 | I11: Nova Sports | J11: 1.60 Nova Sports Clear S/V | K11: 6355 | L11: -766.44 | M11: -397.19 | N11: 4944.17 | O11: 5 | P11: 247.2 | Q11: 5191.37 | R11: 90049090 | S11: CS0141358 | U11: D0069-Darshan Y G | V11: SATINPUV | W11: MIRTMC | X11: IG95 | Y11: Posted | AA11: OCIW14926000412 | AB11: W149-586-17741936712 | AD11: Rx | AE11: =IFERROR(VLOOKUP($B11,Sheet3!B:D,3,0),"") -> BENGALURU | AF11: =IFERROR(VLOOKUP($B11,Sheet3!B:H,7,0),"") -> D. N.CHOWDHURY | AG11: =-(L11) -> 766.44 | AH11: 0
A12: 46113 | B12: W149 | C12: Bangalore - Indira Nagar2 | D12: #149586105650 | F12: 46125 | G12: 1 | H12: 9510992483 | I12: Nova Sports | J12: 1.60 Nova Sports Clear S/V | K12: 6355 | L12: -766.44 | M12: -397.19 | N12: 4944.17 | O12: 5 | P12: 247.2 | Q12: 5191.37 | R12: 90049090 | S12: CS0141358 | U12: D0069-Darshan Y G | V12: SATINPUV | W12: MIRTMC | X12: IG95 | Y12: Posted | AA12: OCIW14926000412 | AB12: W149-586-17741936712 | AD12: Rx | AE12: =IFERROR(VLOOKUP($B12,Sheet3!B:D,3,0),"") -> BENGALURU | AF12: =IFERROR(VLOOKUP($B12,Sheet3!B:H,7,0),"") -> D. N.CHOWDHURY | AG12: =-(L12) -> 766.44 | AH12: 0
A13: 46113 | B13: W149 | C13: Bangalore - Indira Nagar2 | D13: #149586105699 | F13: 46130 | G13: 1 | H13: MTM33BR53 | I13: Tomford FR | J13: TF6106-D-B 052 0 | K13: 44500 | L13: -8900 | M13: 0 | N13: 33904.76 | O13: 5 | P13: 1695.24 | Q13: 35600 | R13: 90031100 | S13: CS0583100 | T13: TF Modstar 20P | U13: D0069-Darshan Y G | X13: IG30 | Y13: Posted | AD13: Only Fr | AE13: =IFERROR(VLOOKUP($B13,Sheet3!B:D,3,0),"") -> BENGALURU | AF13: =IFERROR(VLOOKUP($B13,Sheet3!B:H,7,0),"") -> D. N.CHOWDHURY | AG13: =-(L13) -> 8900 | AH13: =-(L13) -> 8900 | AI13: =G13*500 -> 500
A14: 46113 | B14: W075 | C14: Bangalore - Kormangala | D14: #075536105013 | F14: 46132 | G14: 1 | H14: MTM14BR52 | I14: Tomford FR | J14: TF5617-B 052 | K14: 32000 | L14: -6400 | M14: 0 | N14: 24380.96 | O14: 5 | P14: 1219.04 | Q14: 25600 | R14: 90049090 | S14: CW075-002364 | U14: F0008-Fathimath Naji | X14: IG30 | Y14: Posted | AA14: OCIW07526000235 | AB14: W075-536-17765149970 | AD14: Only Fr | AE14: =IFERROR(VLOOKUP($B14,Sheet3!B:D,3,0),"") -> BENGALURU | AF14: =IFERROR(VLOOKUP($B14,Sheet3!B:H,7,0),"") -> D. N.CHOWDHURY | AG14: =-(L14) -> 6400 | AH14: =-(L14) -> 6400 | AI14: =G14*500 -> 500
A15: 46113 | B15: W075 | C15: Bangalore - Kormangala | D15: #075536105013 | F15: 46132 | G15: 1 | H15: 11178 | I15: Crizal FSV | J15: 1.50 Crizal FSV Clear Easy Pro BCT | K15: 1350 | L15: 0 | M15: 0 | N15: 1285.72 | O15: 5 | P15: 64.28 | Q15: 1350 | R15: 90049090 | S15: CW075-002364 | T15: TF Modstar 20P | U15: F0008-Fathimath Naji | V15: CRIZALESPR | X15: IG001 | Y15: Posted | AA15: OCIW07526000235 | AB15: W075-536-17765149970 | AD15: Rx | AE15: =IFERROR(VLOOKUP($B15,Sheet3!B:D,3,0),"") -> BENGALURU | AF15: =IFERROR(VLOOKUP($B15,Sheet3!B:H,7,0),"") -> D. N.CHOWDHURY | AG15: =-(L15) -> 0 | AH15: 0
A16: 46113 | B16: W075 | C16: Bangalore - Kormangala | D16: #075536105013 | F16: 46132 | G16: 1 | H16: 11178 | I16: Crizal FSV | J16: 1.50 Crizal FSV Clear Easy Pro BCT | K16: 1350 | L16: 0 | M16: 0 | N16: 1285.72 | O16: 5 | P16: 64.28 | Q16: 1350 | R16: 90049090 | S16: CW075-002364 | U16: F0008-Fathimath Naji | V16: CRIZALESPR | X16: IG001 | Y16: Posted | AA16: OCIW07526000235 | AB16: W075-536-17765149970 | AD16: Rx | AE16: =IFERROR(VLOOKUP($B16,Sheet3!B:D,3,0),"") -> BENGALURU | AF16: =IFERROR(VLOOKUP($B16,Sheet3!B:H,7,0),"") -> D. N.CHOWDHURY | AG16: =-(L16) -> 0 | AH16: 0
A17: 46113 | B17: W073 | C17: Puducherry - Mission Street | D17: #073534109595 | F17: 46133 | G17: 1 | H17: MTM19BR54 | I17: Tomford FR | J17: TF5869-B 052 0 ECO | K17: 29400 | L17: -4475.36 | M17: 0 | N17: 23737.76 | O17: 5 | P17: 1186.88 | Q17: 24924.64 | R17: 90049090 | S17: CW073-005137 | U17: G0003-G K Rajesh | X17: IG30 | Y17: Posted | AA17: OCIW07326000416 | AB17: W073-534-17760585573 | AD17: Only Fr | AE17: =IFERROR(VLOOKUP($B17,Sheet3!B:D,3,0),"") -> PUDUCHERRY | AF17: =IFERROR(VLOOKUP($B17,Sheet3!B:H,7,0),"") -> D. N.CHOWDHURY | AG17: =-(L17) -> 4475.36 | AH17: =-(L17) -> 4475.36 | AI17: =G17*500 -> 500
A18: 46113 | B18: W073 | C18: Puducherry - Mission Street | D18: #073534109595 | F18: 46133 | G18: 1 | H18: 9510992623 | I18: Nova Plus Pal | J18: 1.60 Nova Plus 3.0 Pal Gen S Grey SC | K18: 11840 | L18: -1802.32 | M18: 0 | N18: 9559.7 | O18: 5 | P18: 477.98 | Q18: 10037.68 | R18: 90049090 | S18: CW073-005137 | U18: G0003-G K Rajesh | V18: CRIZALRCK | X18: IG95 | Y18: Posted | AA18: OCIW07326000416 | AB18: W073-534-17760585573 | AD18: Rx | AE18: =IFERROR(VLOOKUP($B18,Sheet3!B:D,3,0),"") -> PUDUCHERRY | AF18: =IFERROR(VLOOKUP($B18,Sheet3!B:H,7,0),"") -> D. N.CHOWDHURY | AG18: =-(L18) -> 1802.32 | AH18: 0
A19: 46113 | B19: W073 | C19: Puducherry - Mission Street | D19: #073534109595 | F19: 46133 | G19: 1 | H19: 9510992623 | I19: Nova Plus Pal | J19: 1.60 Nova Plus 3.0 Pal Gen S Grey SC | K19: 11840 | L19: -1802.32 | M19: 0 | N19: 9559.7 | O19: 5 | P19: 477.98 | Q19: 10037.68 | R19: 90049090 | S19: CW073-005137 | U19: G0003-G K Rajesh | V19: CRIZALRCK | X19: IG95 | Y19: Posted | AA19: OCIW07326000416 | AB19: W073-534-17760585573 | AD19: Rx | AE19: =IFERROR(VLOOKUP($B19,Sheet3!B:D,3,0),"") -> PUDUCHERRY | AF19: =IFERROR(VLOOKUP($B19,Sheet3!B:H,7,0),"") -> D. N.CHOWDHURY | AG19: =-(L19) -> 1802.32 | AH19: 0
A20: 46113 | B20: W149 | C20: Bangalore - Indira Nagar2 | D20: #149586105731 | F20: 46133 | G20: 1 | H20: MTM17BR49 | I20: Tomford FR | J20: TF5867-B 052 0 | K20: 29400 | L20: -3528 | M20: 0 | N20: 24640 | O20: 5 | P20: 1232 | Q20: 25872 | R20: 90031100 | S20: CS0196588 | U20: M0113-Md Saeedali K | X20: IG30 | Y20: Posted | AB20: W149-586-17748679769 | AD20: Only Fr | AE20: =IFERROR(VLOOKUP($B20,Sheet3!B:D,3,0),"") -> BENGALURU | AF20: =IFERROR(VLOOKUP($B20,Sheet3!B:H,7,0),"") -> D. N.CHOWDHURY | AG20: =-(L20) -> 3528 | AH20: =-(L20) -> 3528 | AI20: =G20*500 -> 500
A21: 46113 | B21: W149 | C21: Bangalore - Indira Nagar2 | D21: #149586105746 | F21: 46134 | G21: 1 | H21: MTM30BL54 | I21: Tomford SG | J21: TF1273-D 01V 0 ECO | K21: 40100 | L21: -8020 | M21: 0 | N21: 27186.44 | O21: 18 | P21: 4893.56 | Q21: 32080 | R21: 90041000 | S21: CW105-0016394 | T21: TF Modstar 20P | U21: R0100-Rakesh Ghosh | X21: IG100 | Y21: Posted | AB21: W149-586-17765249802 | AD21: Plano Sg | AE21: =IFERROR(VLOOKUP($B21,Sheet3!B:D,3,0),"") -> BENGALURU | AF21: =IFERROR(VLOOKUP($B21,Sheet3!B:H,7,0),"") -> D. N.CHOWDHURY | AG21: =-(L21) -> 8020 | AH21: =-(L21) -> 8020 | AI21: =G21*500 -> 500
A22: 46113 | B22: W149 | C22: Bangalore - Indira Nagar2 | D22: #149586105798 | F22: 46139 | G22: 1 | H22: MTM21BR52 | I22: Tomford FR | J22: TF5898-B 052 0 ECO | K22: 32000 | L22: -2959.2 | M22: 0 | N22: 27657.9 | O22: 5 | P22: 1382.9 | Q22: 29040.8 | R22: 90049090 | S22: CW105-0017186 | U22: D0069-Darshan Y G | X22: IG30 | Y22: Posted | AA22: OCIW14926000413 | AB22: W149-586-17742610549 | AD22: Only Fr | AE22: =IFERROR(VLOOKUP($B22,Sheet3!B:D,3,0),"") -> BENGALURU | AF22: =IFERROR(VLOOKUP($B22,Sheet3!B:H,7,0),"") -> D. N.CHOWDHURY | AG22: =-(L22) -> 2959.2 | AH22: =-(L22) -> 2959.2 | AI22: =G22*500 -> 500
A23: 46113 | B23: W149 | C23: Bangalore - Indira Nagar2 | D23: #149586105798 | F23: 46139 | G23: 1 | H23: 8511201 | I23: NikonPureBlueUV | J23: 1.56 NIKON AS FSV CLEAR PURE BLUE UV ECC | K23: 2450 | L23: -212.4 | M23: -153.13 | N23: 1985.21 | O23: 5 | P23: 99.26 | Q23: 2084.47 | R23: 90049090 | S23: CW105-0017186 | U23: D0069-Darshan Y G | V23: PUBLUV | X23: IG003 | Y23: Posted | AA23: OCIW14926000413 | AB23: W149-586-17742610549 | AD23: Rx | AE23: =IFERROR(VLOOKUP($B23,Sheet3!B:D,3,0),"") -> BENGALURU | AF23: =IFERROR(VLOOKUP($B23,Sheet3!B:H,7,0),"") -> D. N.CHOWDHURY | AG23: =-(L23) -> 212.4 | AH23: 0
A24: 46113 | B24: W149 | C24: Bangalore - Indira Nagar2 | D24: #149586105798 | F24: 46139 | G24: 1 | H24: 8511201 | I24: NikonPureBlueUV | J24: 1.56 NIKON AS FSV CLEAR PURE BLUE UV ECC | K24: 2450 | L24: -212.4 | M24: -153.13 | N24: 1985.21 | O24: 5 | P24: 99.26 | Q24: 2084.47 | R24: 90049090 | S24: CW105-0017186 | U24: D0069-Darshan Y G | V24: PUBLUV | X24: IG003 | Y24: Posted | AA24: OCIW14926000413 | AB24: W149-586-17742610549 | AD24: Rx | AE24: =IFERROR(VLOOKUP($B24,Sheet3!B:D,3,0),"") -> BENGALURU | AF24: =IFERROR(VLOOKUP($B24,Sheet3!B:H,7,0),"") -> D. N.CHOWDHURY | AG24: =-(L24) -> 212.4 | AH24: 0
A25: 46113 | B25: W035 | C25: Ahmedabad - Nexus One | D25: #035523107752 | F25: 46142 | G25: 1 | H25: MTM17BR49 | I25: Tomford FR | J25: TF5867-B 052 0 | K25: 29400 | L25: 0 | M25: 0 | N25: 24915.26 | O25: 18 | P25: 4484.74 | Q25: 29400 | R25: 90049090 | S25: CS0079825 | U25: S0271-Sachin Yadav | X25: IG30 | Y25: Posted | AA25: OCIW03526000269 | AB25: W035-523-17771228879 | AD25: Only Fr | AE25: =IFERROR(VLOOKUP($B25,Sheet3!B:D,3,0),"") -> AHMEDABAD | AF25: =IFERROR(VLOOKUP($B25,Sheet3!B:H,7,0),"") -> DIGVIJAY SINGH | AG25: =-(L25) -> 0 | AH25: =-(L25) -> 0 | AI25: =G25*500 -> 500
A26: 46113 | B26: W035 | C26: Ahmedabad - Nexus One | D26: #035523107752 | F26: 46142 | G26: 1 | H26: 21181143 | I26: Crizal FSV | J26: 1.50 Crizal FSV Gen S Amber Brown | K26: 4450 | L26: 0 | M26: 0 | N26: 3771.18 | O26: 18 | P26: 678.82 | Q26: 4450 | R26: 90049090 | S26: CS0079825 | U26: S0271-Sachin Yadav | V26: CRIZAL | X26: IG001 | Y26: Posted | AA26: OCIW03526000269 | AB26: W035-523-17771228879 | AD26: Rx | AE26: =IFERROR(VLOOKUP($B26,Sheet3!B:D,3,0),"") -> AHMEDABAD | AF26: =IFERROR(VLOOKUP($B26,Sheet3!B:H,7,0),"") -> DIGVIJAY SINGH | AG26: =-(L26) -> 0 | AH26: 0
A27: 46113 | B27: W035 | C27: Ahmedabad - Nexus One | D27: #035523107752 | F27: 46142 | G27: 1 | H27: 21181143 | I27: Crizal FSV | J27: 1.50 Crizal FSV Gen S Amber Brown | K27: 4450 | L27: 0 | M27: 0 | N27: 3771.18 | O27: 18 | P27: 678.82 | Q27: 4450 | R27: 90049090 | S27: CS0079825 | U27: S0271-Sachin Yadav | V27: CRIZAL | X27: IG001 | Y27: Posted | AA27: OCIW03526000269 | AB27: W035-523-17771228879 | AD27: Rx | AE27: =IFERROR(VLOOKUP($B27,Sheet3!B:D,3,0),"") -> AHMEDABAD | AF27: =IFERROR(VLOOKUP($B27,Sheet3!B:H,7,0),"") -> DIGVIJAY SINGH | AG27: =-(L27) -> 0 | AH27: 0
A28: 46143 | B28: W075 | C28: Bangalore - Kormangala | D28: #075536105077 | F28: 46147 | G28: 1 | H28: MTM23BL52 | I28: Tomford FR | J28: TF5939-B 001 0 ECO | K28: 39500 | L28: -7900 | M28: 0 | N28: 30095.24 | O28: 5 | P28: 1504.76 | Q28: 31600 | R28: 90049090 | S28: CS0597015 | T28: TF Modstar 20P | U28: S0008-S Ravi Kumar | X28: IG30 | Y28: Posted | AA28: OCIW07526000268 | AB28: W075-536-17778175180 | AD28: Only Fr | AE28: =IFERROR(VLOOKUP($B28,Sheet3!B:D,3,0),"") -> BENGALURU | AF28: =IFERROR(VLOOKUP($B28,Sheet3!B:H,7,0),"") -> D. N.CHOWDHURY | AG28: =-(L28) -> 7900 | AH28: =-(L28) -> 7900 | AI28: =G28*500 -> 500
A29: 46143 | B29: W075 | C29: Bangalore - Kormangala | D29: #075536105077 | F29: 46147 | G29: 1 | H29: 11185 | I29: Crizal FSV | J29: 1.50 Crizal FSV TGen S Sapphire HR Grey | K29: 4450 | L29: 0 | M29: 0 | N29: 4238.1 | O29: 5 | P29: 211.9 | Q29: 4450 | R29: 90049090 | S29: CS0597015 | U29: S0008-S Ravi Kumar | V29: CRIZALSPHR | X29: IG001 | Y29: Posted | AA29: OCIW07526000268 | AB29: W075-536-17778175180 | AD29: Rx | AE29: =IFERROR(VLOOKUP($B29,Sheet3!B:D,3,0),"") -> BENGALURU | AF29: =IFERROR(VLOOKUP($B29,Sheet3!B:H,7,0),"") -> D. N.CHOWDHURY | AG29: =-(L29) -> 0 | AH29: 0
A30: 46143 | B30: W075 | C30: Bangalore - Kormangala | D30: #075536105077 | F30: 46147 | G30: 1 | H30: 11185 | I30: Crizal FSV | J30: 1.50 Crizal FSV TGen S Sapphire HR Grey | K30: 4450 | L30: 0 | M30: 0 | N30: 4238.1 | O30: 5 | P30: 211.9 | Q30: 4450 | R30: 90049090 | S30: CS0597015 | U30: S0008-S Ravi Kumar | V30: CRIZALSPHR | X30: IG001 | Y30: Posted | AA30: OCIW07526000268 | AB30: W075-536-17778175180 | AD30: Rx | AE30: =IFERROR(VLOOKUP($B30,Sheet3!B:D,3,0),"") -> BENGALURU | AF30: =IFERROR(VLOOKUP($B30,Sheet3!B:H,7,0),"") -> D. N.CHOWDHURY | AG30: =-(L30) -> 0 | AH30: 0
A31: 46143 | B31: W075 | C31: Bangalore - Kormangala | D31: #075536105105 | F31: 46154 | G31: 1 | H31: MTM24BR52 | I31: Tomford FR | J31: TF5939-B 052 0 ECO | K31: 39500 | L31: -7900 | M31: 0 | N31: 30095.24 | O31: 5 | P31: 1504.76 | Q31: 31600 | R31: 90031100 | S31: CS0598966 | T31: TF Modstar 20P | U31: S0008-S Ravi Kumar | X31: IG30 | Y31: Posted | AD31: Only Fr | AE31: =IFERROR(VLOOKUP($B31,Sheet3!B:D,3,0),"") -> BENGALURU | AF31: =IFERROR(VLOOKUP($B31,Sheet3!B:H,7,0),"") -> D. N.CHOWDHURY | AG31: =-(L31) -> 7900 | AH31: =-(L31) -> 7900 | AI31: =G31*500 -> 500
A32: 46143 | B32: W112 | C32: Ranchi - Main Road | D32: #112554107339 | F32: 46156 | G32: 1 | H32: MTM12BR56 | I32: Tomford SG | J32: TF1175 55A 3 ASLAN | K32: 34500 | L32: -3450 | M32: 0 | N32: 29571.42 | O32: 5 | P32: 1478.58 | Q32: 31050 | R32: 90041000 | S32: CW112-000046 | T32: SOCH | U32: T0002-Tanmoy Roy | X32: IG100 | Y32: Posted | AA32: OCIW11226000327 | AB32: W112-554-17782483728 | AD32: Plano Sg | AE32: =IFERROR(VLOOKUP($B32,Sheet3!B:D,3,0),"") -> RANCHI | AF32: =IFERROR(VLOOKUP($B32,Sheet3!B:H,7,0),"") -> JOYDEEP DATTA | AG32: =-(L32) -> 3450 | AH32: =-(L32) -> 3450 | AI32: =G32*500 -> 500
A33: 46143 | B33: W112 | C33: Ranchi - Main Road | D33: #112554107339 | F33: 46156 | G33: 1 | H33: 2011161 | I33: EyePRO SV | J33: 1.50 EyePro Celar Rx | K33: 1650 | L33: 0 | M33: 0 | N33: 1571.42 | O33: 5 | P33: 78.58 | Q33: 1650 | R33: 90041000 | S33: CW112-000046 | U33: T0002-Tanmoy Roy | V33: DHMC+ | W33: TINTCHRG | X33: IG20 | Y33: Posted | AA33: OCIW11226000327 | AB33: W112-554-17782483728 | AD33: Rx | AE33: =IFERROR(VLOOKUP($B33,Sheet3!B:D,3,0),"") -> RANCHI | AF33: =IFERROR(VLOOKUP($B33,Sheet3!B:H,7,0),"") -> JOYDEEP DATTA | AG33: =-(L33) -> 0 | AH33: 0
A34: 46143 | B34: W112 | C34: Ranchi - Main Road | D34: #112554107339 | F34: 46156 | G34: 1 | H34: 2011161 | I34: EyePRO SV | J34: 1.50 EyePro Celar Rx | K34: 1650 | L34: 0 | M34: 0 | N34: 1571.42 | O34: 5 | P34: 78.58 | Q34: 1650 | R34: 90041000 | S34: CW112-000046 | U34: T0002-Tanmoy Roy | V34: DHMC+ | W34: TINTCHRG | X34: IG20 | Y34: Posted | AA34: OCIW11226000327 | AB34: W112-554-17782483728 | AD34: Rx | AE34: =IFERROR(VLOOKUP($B34,Sheet3!B:D,3,0),"") -> RANCHI | AF34: =IFERROR(VLOOKUP($B34,Sheet3!B:H,7,0),"") -> JOYDEEP DATTA | AG34: =-(L34) -> 0 | AH34: 0
A35: 46143 | B35: W073 | C35: Puducherry - Mission Street | D35: #073534109842 | F35: 46159 | G35: 1 | H35: MTM29GR56 | I35: Tomford FR | J35: TF5801-F-B 001 0 (BLACK) | K35: 45000 | L35: -9000 | M35: 0 | N35: 34285.72 | O35: 5 | P35: 1714.28 | Q35: 36000 | R35: 90049090 | S35: CS0599259 | T35: TF Modstar 20P | U35: G0003-G K Rajesh | X35: IG30 | Y35: Posted | AA35: OCIW07326000527 | AB35: W073-534-17786514271 | AD35: Only Fr | AE35: =IFERROR(VLOOKUP($B35,Sheet3!B:D,3,0),"") -> PUDUCHERRY | AF35: =IFERROR(VLOOKUP($B35,Sheet3!B:H,7,0),"") -> D. N.CHOWDHURY | AG35: =-(L35) -> 9000 | AH35: =-(L35) -> 9000 | AI35: =G35*500 -> 500
A36: 46143 | B36: W073 | C36: Puducherry - Mission Street | D36: #073534109842 | F36: 46159 | G36: 1 | H36: 111713 | I36: Crizal FSV | J36: 1.59 Crizal FSV Clear Easy Pro BCT | K36: 2050 | L36: 0 | M36: 0 | N36: 1952.38 | O36: 5 | P36: 97.62 | Q36: 2050 | R36: 90049090 | S36: CS0599259 | U36: G0003-G K Rajesh | V36: CRIZALESPR | X36: IG001 | Y36: Posted | AA36: OCIW07326000527 | AB36: W073-534-17786514271 | AD36: Rx | AE36: =IFERROR(VLOOKUP($B36,Sheet3!B:D,3,0),"") -> PUDUCHERRY | AF36: =IFERROR(VLOOKUP($B36,Sheet3!B:H,7,0),"") -> D. N.CHOWDHURY | AG36: =-(L36) -> 0 | AH36: 0
A37: 46143 | B37: W073 | C37: Puducherry - Mission Street | D37: #073534109842 | F37: 46159 | G37: 1 | H37: 111713 | I37: Crizal FSV | J37: 1.59 Crizal FSV Clear Easy Pro BCT | K37: 2050 | L37: 0 | M37: 0 | N37: 1952.38 | O37: 5 | P37: 97.62 | Q37: 2050 | R37: 90049090 | S37: CS0599259 | U37: G0003-G K Rajesh | V37: CRIZALESPR | X37: IG001 | Y37: Posted | AA37: OCIW07326000527 | AB37: W073-534-17786514271 | AD37: Rx | AE37: =IFERROR(VLOOKUP($B37,Sheet3!B:D,3,0),"") -> PUDUCHERRY | AF37: =IFERROR(VLOOKUP($B37,Sheet3!B:H,7,0),"") -> D. N.CHOWDHURY | AG37: =-(L37) -> 0 | AH37: 0
A38: 46143 | B38: W117 | C38: Gurgaon - Arjun Marg | D38: #117557106704 | F38: 46162 | G38: 1 | H38: MTM22BR54 | I38: Tomford FR | J38: TF5938-B 057 0 ECO | K38: 32500 | L38: 0 | M38: 0 | N38: 30952.38 | O38: 5 | P38: 1547.62 | Q38: 32500 | R38: 90049090 | S38: CS0600078 | U38: V0013-Vivek Kumar | X38: IG30 | Y38: Posted | AA38: OCIW11726000370 | AB38: W117-557-17789433818 | AD38: Only Fr | AE38: =IFERROR(VLOOKUP($B38,Sheet3!B:D,3,0),"") -> GURUGRAM | AF38: =IFERROR(VLOOKUP($B38,Sheet3!B:H,7,0),"") -> AMANDEEP SINGH GILL | AG38: =-(L38) -> 0 | AH38: =-(L38) -> 0 | AI38: =G38*500 -> 500
A39: 46143 | B39: W117 | C39: Gurgaon - Arjun Marg | D39: #117557106704 | F39: 46162 | G39: 1 | H39: 9510821860 | I39: Blumax Nova UHD | J39: 1.56 XT Nova UHD Blumax Short | K39: 12960 | L39: -6480 | M39: 0 | N39: 6171.42 | O39: 5 | P39: 308.58 | Q39: 6480 | R39: 90049090 | S39: CS0600078 | T39: Crizal Hapiness | U39: V0013-Vivek Kumar | V39: CRIZALRCK | X39: IG95 | Y39: Posted | AA39: OCIW11726000370 | AB39: W117-557-17789433818 | AD39: Rx | AE39: =IFERROR(VLOOKUP($B39,Sheet3!B:D,3,0),"") -> GURUGRAM | AF39: =IFERROR(VLOOKUP($B39,Sheet3!B:H,7,0),"") -> AMANDEEP SINGH GILL | AG39: =-(L39) -> 6480 | AH39: 0
A40: 46143 | B40: W117 | C40: Gurgaon - Arjun Marg | D40: #117557106704 | F40: 46162 | G40: 1 | H40: 9510821860 | I40: Blumax Nova UHD | J40: 1.56 XT Nova UHD Blumax Short | K40: 12960 | L40: -6480 | M40: 0 | N40: 6171.42 | O40: 5 | P40: 308.58 | Q40: 6480 | R40: 90049090 | S40: CS0600078 | T40: Crizal Hapiness | U40: V0013-Vivek Kumar | V40: CRIZALRCK | X40: IG95 | Y40: Posted | AA40: OCIW11726000370 | AB40: W117-557-17789433818 | AD40: Rx | AE40: =IFERROR(VLOOKUP($B40,Sheet3!B:D,3,0),"") -> GURUGRAM | AF40: =IFERROR(VLOOKUP($B40,Sheet3!B:H,7,0),"") -> AMANDEEP SINGH GILL | AG40: =-(L40) -> 6480 | AH40: 0
...

Sheet Offer On selected SKU
A1: Offer Only Valid for below Models
A3: Item Id | B3: Model No
A4: MTM10MS55 | B4: FT1108
A5: MTM11BR56 | B5: FT1175
A6: MTM12BR56 | B6: FT1175
A7: MTM13BR53 | B7: FT1213
A8: MTM14BR52 | B8: FT5617-B
A9: MTM15BR53 | B9: FT5699-B
A10: MTM16GR49 | B10: FT5867-B
A11: MTM17BR49 | B11: FT5867-B
A12: MTM18BL54 | B12: FT5869-B
A13: MTM19BR54 | B13: FT5869-B
A14: MTM1LG53 | B14: FT0248
... A36: MTM9BR55 | B36: FT1108

Sheet Sheet3
A1: SNo. | B1: Store Code | C1: Showroom Loc / Name | D1: City | E1: State | F1: Opening Date | G1: Store Mail ID | H1: Business Development Manager | I1: Showroom Manager/Incharge
A2: 1 | B2: W168 | C2: SUMMIT PLAZA | D2: GURUGRAM | E2: DELHI & NCR | F2: 46245 | G2: summitplaza@gkblens.com | H2: AMANDEEP SINGH GILL | I2: NEERA
A3: 2 | B3: W134 | C3: BIAL INTERNATIONAL | D3: BENGALURU | E3: KARNATAKA | F3: 46210 | G3: gkbbial2@gkblens.com | H3: D. N.CHOWDHURY | I3: SYED MUHEEB
A4: 3 | B4: W023 | C4: GREEN PARK | D4: NEW DELHI | E4: DELHI & NCR | F4: 46108 | G4: delhigreenpark@gkblens.com | H4: AMANDEEP SINGH GILL | I4: AJEET KUMAR SHARMA
A5: 4 | B5: W139 | C5: MOTINAGAR | D5: NEW DELHI | E5: DELHI & NCR | F5: 46093 | G5: delhimotinagar@gkblens.com | H5: AMANDEEP SINGH GILL | I5: PARBJEET KAUR
A6: 5 | B6: W167 | C6: HUDA MARKET | D6: GURUGRAM | E6: DELHI & NCR | F6: 46017 | G6: gurgaonhuda@gkblens.com | H6: AMANDEEP SINGH GILL | I6: ANIL KUMAR SINGH
A7: 6 | B7: W024 | C7: LAKESHORE GATEWAY MALL | D7: HYDERABAD | E7: TELANGANA | F7: 46003 | G7: hyderabadgateway@gkblens.com | H7: AMANDEEP SINGH GILL | I7: A J REDDY
A8: 7 | B8: W166 | C8: UNITY ONE ELEGANT MALL | D8: NEW DELHI | E8: DELHI & NCR | F8: 45946 | G8: nspdelhi@gkblens.com | H8: AMANDEEP SINGH GILL | I8: SUMIT KUMAR
A9: 8 | B9: W165 | C9: SKY CITY MALL | D9: MUMBAI | E9: MAHARASTRA | F9: 45837 | G9: skycitymumbai@gkblens.com | H9: DIGVIJAY SINGH | I9: SHRUSHTI SHAILESH BARBHAYA
A10: 9 | B10: W164 | C10: HSR Layout | D10: BENGALURU | E10: KARNATAKA | F10: 45674 | G10: hsrbangalore@gkblens.com | H10: D. N.CHOWDHURY | I10: ATAL BIHARI
A11: 10 | B11: W163 | C11: Maybach Icons of Luxury | D11: BENGALURU | E11: KARNATAKA | F11: 45674 | G11: blrmaybach@gkblens.com | H11: D. N.CHOWDHURY | I11: BOPANNA M S
A12: 11 | B12: W162 | C12: Omaxe Chandni Chowk | D12: DELHI | E12: DELHI & NCR | F12: 45644 | G12: delhiomaxe@gkblens.com | H12: AMANDEEP SINGH GILL | I12: SUMIT VERMA
A13: 12 | B13: W161 | C13: M5 E City Mall | D13: BENGALURU | E13: KARNATAKA | F13: 45591 | G13: m5bangalore@gkblens.com | H13: D. N.CHOWDHURY | I13: R BALACHANDRAN
... A99: 98 | B99: W500 | C99: GARIAHAT | D99: KOLKATA | E99: WEST BENGAL | F99: 24915 | G99: gkbgariahat@gkblens.com | H99: JOYDEEP DATTA | I99: PULAK DASGUPTA
